Workbook

Sheet Ringkasan
A1: Perbandingan Stok SCM (7 Okt 2026) vs SO Gudang (30 Sep 2026)
B3: Nominal (Rp)
A4: Total SO | B4: =SUM('Data SO'!$G$2:$G$1085) -> 2.0844897e+09
A5: Total SCM | B5: =SUM('Data SCM'!$H$2:$H$698) -> 2.0680255e+09
A6: Selisih (SCM − SO) | B6: =B5-B4 -> -16464273
A8: Keterangan | B8: Jumlah Barang | C8: Selisih Nominal (Rp)
A9: Sama | B9: =COUNTIF(Perbandingan!$I$2:$I$453,A9) -> 320 | C9: =SUMIF(Perbandingan!$I$2:$I$453,A9,Perbandingan!$H$2:$H$453) -> -0.40290367
A10: Selisih nominal | B10: =COUNTIF(Perbandingan!$I$2:$I$453,A10) -> 2 | C10: =SUMIF(Perbandingan!$I$2:$I$453,A10,Perbandingan!$H$2:$H$453) -> -7451538.5
A11: Selisih qty | B11: =COUNTIF(Perbandingan!$I$2:$I$453,A11) -> 5 | C11: =SUMIF(Perbandingan!$I$2:$I$453,A11,Perbandingan!$H$2:$H$453) -> 0.228
A12: Selisih qty & nominal | B12: =COUNTIF(Perbandingan!$I$2:$I$453,A12) -> 88 | C12: =SUMIF(Perbandingan!$I$2:$I$453,A12,Perbandingan!$H$2:$H$453) -> 27653532
A13: Hanya di SO | B13: =COUNTIF(Perbandingan!$I$2:$I$453,A13) -> 29 | C13: =SUMIF(Perbandingan!$I$2:$I$453,A13,Perbandingan!$H$2:$H$453) -> -41057436
A14: Hanya di SCM | B14: =COUNTIF(Perbandingan!$I$2:$I$453,A14) -> 8 | C14: =SUMIF(Perbandingan!$I$2:$I$453,A14,Perbandingan!$H$2:$H$453) -> 4391168.7
A15: Total | B15: =SUM(B9:B14) -> 452 | C15: =SUM(C9:C14) -> -16464273
A17: Pencocokan berdasarkan nama barang. Qty SCM sudah disetarakan ke satuan SO (gram→kg, ml→liter). Beda tanggal (30 Sep vs 7 Okt) bisa memengaruhi selisih.

Sheet Perbandingan
A1: Nama Barang | B1: Satuan | C1: Qty SO | D1: Qty SCM | E1: Selisih Qty | F1: Nominal SO (Rp) | G1: Nominal SCM (Rp) | H1: Selisih Nominal (Rp) | I1: Keterangan | J1: Key | K1: Satuan SCM | L1: Faktor | M1: Keterangan 2
A2: =IFERROR(INDEX('Data SO'!$C$2:$C$1085,MATCH($J2,'Data SO'!$H$2:$H$1085,0)),INDEX('Data SCM'!$B$2:$B$698,MATCH($J2,'Data SCM'!$I$2:$I$698,0))) -> TRANS WHIPPING CREAM - GOLD | B2: =IFERROR(INDEX('Data SO'!$D$2:$D$1085,MATCH($J2,'Data SO'!$H$2:$H$1085,0)),K2) -> Kg | C2: =SUMIF('Data SO'!$H$2:$H$1085,$J2,'Data SO'!$F$2:$F$1085) -> 0 | D2: =SUMIF('Data SCM'!$I$2:$I$698,$J2,'Data SCM'!$E$2:$E$698)*L2 -> 563.9992 | E2: =D2-C2 -> 563.9992 | F2: =SUMIF('Data SO'!$H$2:$H$1085,$J2,'Data SO'!$G$2:$G$1085) -> 0 | G2: =SUMIF('Data SCM'!$I$2:$I$698,$J2,'Data SCM'!$H$2:$H$698) -> 27071961 | H2: =G2-F2 -> 27071961 | I2: =IF(COUNTIF('Data SCM'!$I$2:$I$698,$J2)=0,"Hanya di SO",IF(COUNTIF('Data SO'!$H$2:$H$1085,$J2)=0,"Hanya di SCM",IF(AND(ABS(E2)<0.01,ABS(H2)<1),"Sama",IF(ABS(E2)<0.01,"Selisih nominal",IF(ABS(H2)<1,"Selisih qty","Selisih qty & nominal"))))) -> Selisih qty & nominal | J2: transwhippingcreamgold | K2: =IFERROR(INDEX('Data SCM'!$D$2:$D$698,MATCH($J2,'Data SCM'!$I$2:$I$698,0)),"") -> KG | L2: =IF(OR(AND(K2="GR",LOWER(B2)="kg"),AND(K2="ML",LOWER(B2)="liter")),0.001,1) -> 1 | M2: yang betul stok 0
A3: =IFERROR(INDEX('Data SO'!$C$2:$C$1085,MATCH($J3,'Data SO'!$H$2:$H$1085,0)),INDEX('Data SCM'!$B$2:$B$698,MATCH($J3,'Data SCM'!$I$2:$I$698,0))) -> Hand Glove Plastik | B3: =IFERROR(INDEX('Data SO'!$D$2:$D$1085,MATCH($J3,'Data SO'!$H$2:$H$1085,0)),K3) -> Pcs | C3: =SUMIF('Data SO'!$H$2:$H$1085,$J3,'Data SO'!$F$2:$F$1085) -> 35 | D3: =SUMIF('Data SCM'!$I$2:$I$698,$J3,'Data SCM'!$E$2:$E$698)*L3 -> 3500 | E3: =D3-C3 -> 3465 | F3: =SUMIF('Data SO'!$H$2:$H$1085,$J3,'Data SO'!$G$2:$G$1085) -> 239750 | G3: =SUMIF('Data SCM'!$I$2:$I$698,$J3,'Data SCM'!$H$2:$H$698) -> 23975000 | H3: =G3-F3 -> 23735250 | I3: =IF(COUNTIF('Data SCM'!$I$2:$I$698,$J3)=0,"Hanya di SO",IF(COUNTIF('Data SO'!$H$2:$H$1085,$J3)=0,"Hanya di SCM",IF(AND(ABS(E3)<0.01,ABS(H3)<1),"Sama",IF(ABS(E3)<0.01,"Selisih nominal",IF(ABS(H3)<1,"Selisih qty","Selisih qty & nominal"))))) -> Selisih qty & nominal | J3: handgloveplastik | K3: =IFERROR(INDEX('Data SCM'!$D$2:$D$698,MATCH($J3,'Data SCM'!$I$2:$I$698,0)),"") -> PCS | L3: =IF(OR(AND(K3="GR",LOWER(B3)="kg"),AND(K3="ML",LOWER(B3)="liter")),0.001,1) -> 1 | M3: Yang betul stok 35 pak karena harga yang tercantum per pak
A4: =IFERROR(INDEX('Data SO'!$C$2:$C$1085,MATCH($J4,'Data SO'!$H$2:$H$1085,0)),INDEX('Data SCM'!$B$2:$B$698,MATCH($J4,'Data SCM'!$I$2:$I$698,0))) -> Plastik Opp 15X25 | B4: =IFERROR(INDEX('Data SO'!$D$2:$D$1085,MATCH($J4,'Data SO'!$H$2:$H$1085,0)),K4) -> Pcs | C4: =SUMIF('Data SO'!$H$2:$H$1085,$J4,'Data SO'!$F$2:$F$1085) -> 73000 | D4: =SUMIF('Data SCM'!$I$2:$I$698,$J4,'Data SCM'!$E$2:$E$698)*L4 -> 0 | E4: =D4-C4 -> -73000 | F4: =SUMIF('Data SO'!$H$2:$H$1085,$J4,'Data SO'!$G$2:$G$1085) -> 23652000 | G4: =SUMIF('Data SCM'!$I$2:$I$698,$J4,'Data SCM'!$H$2:$H$698) -> 0 | H4: =G4-F4 -> -23652000 | I4: =IF(COUNTIF('Data SCM'!$I$2:$I$698,$J4)=0,"Hanya di SO",IF(COUNTIF('Data SO'!$H$2:$H$1085,$J4)=0,"Hanya di SCM",IF(AND(ABS(E4)<0.01,ABS(H4)<1),"Sama",IF(ABS(E4)<0.01,"Selisih nominal",IF(ABS(H4)<1,"Selisih qty","Selisih qty & nominal"))))) -> Hanya di SO | J4: plastikopp15x25 | K4: =IFERROR(INDEX('Data SCM'!$D$2:$D$698,MATCH($J4,'Data SCM'!$I$2:$I$698,0)),"") | L4: =IF(OR(AND(K4="GR",LOWER(B4)="kg"),AND(K4="ML",LOWER(B4)="liter")),0.001,1) -> 1 | M4: yang betul 73.000 pcs stok fisiknya
A5: =IFERROR(INDEX('Data SO'!$C$2:$C$1085,MATCH($J5,'Data SO'!$H$2:$H$1085,0)),INDEX('Data SCM'!$B$2:$B$698,MATCH($J5,'Data SCM'!$I$2:$I$698,0))) -> PREMIX GULA BROWNIES | B5: =IFERROR(INDEX('Data SO'!$D$2:$D$1085,MATCH($J5,'Data SO'!$H$2:$H$1085,0)),K5) -> Pcs | C5: =SUMIF('Data SO'!$H$2:$H$1085,$J5,'Data SO'!$F$2:$F$1085) -> 0 | D5: =SUMIF('Data SCM'!$I$2:$I$698,$J5,'Data SCM'!$E$2:$E$698)*L5 -> 83 | E5: =D5-C5 -> 83 | F5: =SUMIF('Data SO'!$H$2:$H$1085,$J5,'Data SO'!$G$2:$G$1085) -> 0 | G5: =SUMIF('Data SCM'!$I$2:$I$698,$J5,'Data SCM'!$H$2:$H$698) -> 12191751 | H5: =G5-F5 -> 12191751 | I5: =IF(COUNTIF('Data SCM'!$I$2:$I$698,$J5)=0,"Hanya di SO",IF(COUNTIF('Data SO'!$H$2:$H$1085,$J5)=0,"Hanya di SCM",IF(AND(ABS(E5)<0.01,ABS(H5)<1),"Sama",IF(ABS(E5)<0.01,"Selisih nominal",IF(ABS(H5)<1,"Selisih qty","Selisih qty & nominal"))))) -> Selisih qty & nominal | J5: premixgulabrownies | K5: =IFERROR(INDEX('Data SCM'!$D$2:$D$698,MATCH($J5,'Data SCM'!$I$2:$I$698,0)),"") -> PCS | L5: =IF(OR(AND(K5="GR",LOWER(B5)="kg"),AND(K5="ML",LOWER(B5)="liter")),0.001,1) -> 1 | M5: yang betul stok 83
A6: =IFERROR(INDEX('Data SO'!$C$2:$C$1085,MATCH($J6,'Data SO'!$H$2:$H$1085,0)),INDEX('Data SCM'!$B$2:$B$698,MATCH($J6,'Data SCM'!$I$2:$I$698,0))) -> TEGRAL MOCHI BREAD | B6: =IFERROR(INDEX('Data SO'!$D$2:$D$1085,MATCH($J6,'Data SO'!$H$2:$H$1085,0)),K6) -> kg | C6: =SUMIF('Data SO'!$H$2:$H$1085,$J6,'Data SO'!$F$2:$F$1085) -> 0 | D6: =SUMIF('Data SCM'!$I$2:$I$698,$J6,'Data SCM'!$E$2:$E$698)*L6 -> 100 | E6: =D6-C6 -> 100 | F6: =SUMIF('Data SO'!$H$2:$H$1085,$J6,'Data SO'!$G$2:$G$1085) -> 0 | G6: =SUMIF('Data SCM'!$I$2:$I$698,$J6,'Data SCM'!$H$2:$H$698) -> 8580300 | H6: =G6-F6 -> 8580300 | I6: =IF(COUNTIF('Data SCM'!$I$2:$I$698,$J6)=0,"Hanya di SO",IF(COUNTIF('Data SO'!$H$2:$H$1085,$J6)=0,"Hanya di SCM",IF(AND(ABS(E6)<0.01,ABS(H6)<1),"Sama",IF(ABS(E6)<0.01,"Selisih nominal",IF(ABS(H6)<1,"Selisih qty","Selisih qty & nominal"))))) -> Selisih qty & nominal | J6: tegralmochibread | K6: =IFERROR(INDEX('Data SCM'!$D$2:$D$698,MATCH($J6,'Data SCM'!$I$2:$I$698,0)),"") -> KG | L6: =IF(OR(AND(K6="GR",LOWER(B6)="kg"),AND(K6="ML",LOWER(B6)="liter")),0.001,1) -> 1 | M6: yang betul 100 kg
A7: =IFERROR(INDEX('Data SO'!$C$2:$C$1085,MATCH($J7,'Data SO'!$H$2:$H$1085,0)),INDEX('Data SCM'!$B$2:$B$698,MATCH($J7,'Data SCM'!$I$2:$I$698,0))) -> PEWARNA CROSS ORANGE @60 ML | B7: =IFERROR(INDEX('Data SO'!$D$2:$D$1085,MATCH($J7,'Data SO'!$H$2:$H$1085,0)),K7) -> Pcs | C7: =SUMIF('Data SO'!$H$2:$H$1085,$J7,'Data SO'!$F$2:$F$1085) -> 240 | D7: =SUMIF('Data SCM'!$I$2:$I$698,$J7,'Data SCM'!$E$2:$E$698)*L7 -> 240 | E7: =D7-C7 -> 0 | F7: =SUMIF('Data SO'!$H$2:$H$1085,$J7,'Data SO'!$G$2:$G$1085) -> 7200000 | G7: =SUMIF('Data SCM'!$I$2:$I$698,$J7,'Data SCM'!$H$2:$H$698) -> 120000 | H7: =G7-F7 -> -7080000 | I7: =IF(COUNTIF('Data SCM'!$I$2:$I$698,$J7)=0,"Hanya di SO",IF(COUNTIF('Data SO'!$H$2:$H$1085,$J7)=0,"Hanya di SCM",IF(AND(ABS(E7)<0.01,ABS(H7)<1),"Sama",IF(ABS(E7)<0.01,"Selisih nominal",IF(ABS(H7)<1,"Selisih qty","Selisih qty & nominal"))))) -> Selisih nominal | J7: pewarnacrossorange60ml | K7: =IFERROR(INDEX('Data SCM'!$D$2:$D$698,MATCH($J7,'Data SCM'!$I$2:$I$698,0)),"") -> ML | L7: =IF(OR(AND(K7="GR",LOWER(B7)="kg"),AND(K7="ML",LOWER(B7)="liter")),0.001,1) -> 1 | M7: nominal yang betul 120.000
A8: =IFERROR(INDEX('Data SO'!$C$2:$C$1085,MATCH($J8,'Data SO'!$H$2:$H$1085,0)),INDEX('Data SCM'!$B$2:$B$698,MATCH($J8,'Data SCM'!$I$2:$I$698,0))) -> Cover Dessert Blueberry | B8: =IFERROR(INDEX('Data SO'!$D$2:$D$1085,MATCH($J8,'Data SO'!$H$2:$H$1085,0)),K8) -> Pcs | C8: =SUMIF('Data SO'!$H$2:$H$1085,$J8,'Data SO'!$F$2:$F$1085) -> 4800 | D8: =SUMIF('Data SCM'!$I$2:$I$698,$J8,'Data SCM'!$E$2:$E$698)*L8 -> 0 | E8: =D8-C8 -> -4800 | F8: =SUMIF('Data SO'!$H$2:$H$1085,$J8,'Data SO'!$G$2:$G$1085) -> 6960000 | G8: =SUMIF('Data SCM'!$I$2:$I$698,$J8,'Data SCM'!$H$2:$H$698) -> 0 | H8: =G8-F8 -> -6960000 | I8: =IF(COUNTIF('Data SCM'!$I$2:$I$698,$J8)=0,"Hanya di SO",IF(COUNTIF('Data SO'!$H$2:$H$1085,$J8)=0,"Hanya di SCM",IF(AND(ABS(E8)<0.01,ABS(H8)<1),"Sama",IF(ABS(E8)<0.01,"Selisih nominal",IF(ABS(H8)<1,"Selisih qty","Selisih qty & nominal"))))) -> Selisih qty & nominal | J8: coverdessertblueberry | K8: =IFERROR(INDEX('Data SCM'!$D$2:$D$698,MATCH($J8,'Data SCM'!$I$2:$I$698,0)),"") -> PCS | L8: =IF(OR(AND(K8="GR",LOWER(B8)="kg"),AND(K8="ML",LOWER(B8)="liter")),0.001,1) -> 1 | M8: yang betul stok 4800
A9: =IFERROR(INDEX('Data SO'!$C$2:$C$1085,MATCH($J9,'Data SO'!$H$2:$H$1085,0)),INDEX('Data SCM'!$B$2:$B$698,MATCH($J9,'Data SCM'!$I$2:$I$698,0))) -> PASTRICIA DUSTING SUGAR @1X10KG | B9: =IFERROR(INDEX('Data SO'!$D$2:$D$1085,MATCH($J9,'Data SO'!$H$2:$H$1085,0)),K9) -> Kg | C9: =SUMIF('Data SO'!$H$2:$H$1085,$J9,'Data SO'!$F$2:$F$1085) -> 160 | D9: =SUMIF('Data SCM'!$I$2:$I$698,$J9,'Data SCM'!$E$2:$E$698)*L9 -> 16 | E9: =D9-C9 -> -144 | F9: =SUMIF('Data SO'!$H$2:$H$1085,$J9,'Data SO'!$G$2:$G$1085) -> 7104000 | G9: =SUMIF('Data SCM'!$I$2:$I$698,$J9,'Data SCM'!$H$2:$H$698) -> 710400 | H9: =G9-F9 -> -6393600 | I9: =IF(COUNTIF('Data SCM'!$I$2:$I$698,$J9)=0,"Hanya di SO",IF(COUNTIF('Data SO'!$H$2:$H$1085,$J9)=0,"Hanya di SCM",IF(AND(ABS(E9)<0.01,ABS(H9)<1),"Sama",IF(ABS(E9)<0.01,"Selisih nominal",IF(ABS(H9)<1,"Selisih qty","Selisih qty & nominal"))))) -> Selisih qty & nominal | J9: pastriciadustingsugar1x10kg | K9: =IFERROR(INDEX('Data SCM'!$D$2:$D$698,MATCH($J9,'Data SCM'!$I$2:$I$698,0)),"") -> GR | L9: =IF(OR(AND(K9="GR",LOWER(B9)="kg"),AND(K9="ML",LOWER(B9)="liter")),0.001,1) -> 0.001 | M9: yang betul stok 160
A10: =IFERROR(INDEX('Data SO'!$C$2:$C$1085,MATCH($J10,'Data SO'!$H$2:$H$1085,0)),INDEX('Data SCM'!$B$2:$B$698,MATCH($J10,'Data SCM'!$I$2:$I$698,0))) -> Dus General @250 Pcs | B10: =IFERROR(INDEX('Data SO'!$D$2:$D$1085,MATCH($J10,'Data SO'!$H$2:$H$1085,0)),K10) -> pcs | C10: =SUMIF('Data SO'!$H$2:$H$1085,$J10,'Data SO'!$F$2:$F$1085) -> 2350 | D10: =SUMIF('Data SCM'!$I$2:$I$698,$J10,'Data SCM'!$E$2:$E$698)*L10 -> 0 | E10: =D10-C10 -> -2350 | F10: =SUMIF('Data SO'!$H$2:$H$1085,$J10,'Data SO'!$G$2:$G$1085) -> 6129975 | G10: =SUMIF('Data SCM'!$I$2:$I$698,$J10,'Data SCM'!$H$2:$H$698) -> 0 | H10: =G10-F10 -> -6129975 | I10: =IF(COUNTIF('Data SCM'!$I$2:$I$698,$J10)=0,"Hanya di SO",IF(COUNTIF('Data SO'!$H$2:$H$1085,$J10)=0,"Hanya di SCM",IF(AND(ABS(E10)<0.01,ABS(H10)<1),"Sama",IF(ABS(E10)<0.01,"Selisih nominal",IF(ABS(H10)<1,"Selisih qty","Selisih qty & nominal"))))) -> Selisih qty & nominal | J10: dusgeneral250pcs | K10: =IFERROR(INDEX('Data SCM'!$D$2:$D$698,MATCH($J10,'Data SCM'!$I$2:$I$698,0)),"") -> PCS | L10: =IF(OR(AND(K10="GR",LOWER(B10)="kg"),AND(K10="ML",LOWER(B10)="liter")),0.001,1) -> 1 | M10: yang betul stok 2350
A11: =IFERROR(INDEX('Data SO'!$C$2:$C$1085,MATCH($J11,'Data SO'!$H$2:$H$1085,0)),INDEX('Data SCM'!$B$2:$B$698,MATCH($J11,'Data SCM'!$I$2:$I$698,0))) -> Terigu Stupa Hijau @25Kg | B11: =IFERROR(INDEX('Data SO'!$D$2:$D$1085,MATCH($J11,'Data SO'!$H$2:$H$1085,0)),K11) -> kg | C11: =SUMIF('Data SO'!$H$2:$H$1085,$J11,'Data SO'!$F$2:$F$1085) -> 0 | D11: =SUMIF('Data SCM'!$I$2:$I$698,$J11,'Data SCM'!$E$2:$E$698)*L11 -> 725 | E11: =D11-C11 -> 725 | F11: =SUMIF('Data SO'!$H$2:$H$1085,$J11,'Data SO'!$G$2:$G$1085) -> 0 | G11: =SUMIF('Data SCM'!$I$2:$I$698,$J11,'Data SCM'!$H$2:$H$698) -> 5951158.9 | H11: =G11-F11 -> 5951158.9 | I11: =IF(COUNTIF('Data SCM'!$I$2:$I$698,$J11)=0,"Hanya di SO",IF(COUNTIF('Data SO'!$H$2:$H$1085,$J11)=0,"Hanya di SCM",IF(AND(ABS(E11)<0.01,ABS(H11)<1),"Sama",IF(ABS(E11)<0.01,"Selisih nominal",IF(ABS(H11)<1,"Selisih qty","Selisih qty & nominal"))))) -> Selisih qty & nominal | J11: terigustupahijau25kg | K11: =IFERROR(INDEX('Data SCM'!$D$2:$D$698,MATCH($J11,'Data SCM'!$I$2:$I$698,0)),"") -> KG | L11: =IF(OR(AND(K11="GR",LOWER(B11)="kg"),AND(K11="ML",LOWER(B11)="liter")),0.001,1) -> 1 | M11: yang betul stok nya 0
A12: =IFERROR(INDEX('Data SO'!$C$2:$C$1085,MATCH($J12,'Data SO'!$H$2:$H$1085,0)),INDEX('Data SCM'!$B$2:$B$698,MATCH($J12,'Data SCM'!$I$2:$I$698,0))) -> HIRA MANNA SP 20KG | B12: =IFERROR(INDEX('Data SO'!$D$2:$D$1085,MATCH($J12,'Data SO'!$H$2:$H$1085,0)),K12) -> kg | C12: =SUMIF('Data SO'!$H$2:$H$1085,$J12,'Data SO'!$F$2:$F$1085) -> 7 | D12: =SUMIF('Data SCM'!$I$2:$I$698,$J12,'Data SCM'!$E$2:$E$698)*L12 -> 0 | E12: =D12-C12 -> -7 | F12: =SUMIF('Data SO'!$H$2:$H$1085,$J12,'Data SO'!$G$2:$G$1085) -> 5530000 | G12: =SUMIF('Data SCM'!$I$2:$I$698,$J12,'Data SCM'!$H$2:$H$698) -> 0 | H12: =G12-F12 -> -5530000 | I12: =IF(COUNTIF('Data SCM'!$I$2:$I$698,$J12)=0,"Hanya di SO",IF(COUNTIF('Data SO'!$H$2:$H$1085,$J12)=0,"Hanya di SCM",IF(AND(ABS(E12)<0.01,ABS(H12)<1),"Sama",IF(ABS(E12)<0.01,"Selisih nominal",IF(ABS(H12)<1,"Selisih qty","Selisih qty & nominal"))))) -> Selisih qty & nominal | J12: hiramannasp20kg | K12: =IFERROR(INDEX('Data SCM'!$D$2:$D$698,MATCH($J12,'Data SCM'!$I$2:$I$698,0)),"") -> KG | L12: =IF(OR(AND(K12="GR",LOWER(B12)="kg"),AND(K12="ML",LOWER(B12)="liter")),0.001,1) -> 1 | M12: yang betul 0 di stok nominal jg 0
A13: =IFERROR(INDEX('Data SO'!$C$2:$C$1085,MATCH($J13,'Data SO'!$H$2:$H$1085,0)),INDEX('Data SCM'!$B$2:$B$698,MATCH($J13,'Data SCM'!$I$2:$I$698,0))) -> Crystal Jelly @5Kg | B13: =IFERROR(INDEX('Data SO'!$D$2:$D$1085,MATCH($J13,'Data SO'!$H$2:$H$1085,0)),K13) -> kg | C13: =SUMIF('Data SO'!$H$2:$H$1085,$J13,'Data SO'!$F$2:$F$1085) -> 5 | D13: =SUMIF('Data SCM'!$I$2:$I$698,$J13,'Data SCM'!$E$2:$E$698)*L13 -> 80 | E13: =D13-C13 -> 75 | F13: =SUMIF('Data SO'!$H$2:$H$1085,$J13,'Data SO'!$G$2:$G$1085) -> 355963 | G13: =SUMIF('Data SCM'!$I$2:$I$698,$J13,'Data SCM'!$H$2:$H$698) -> 5695408 | H13: =G13-F13 -> 5339445 | I13: =IF(COUNTIF('Data SCM'!$I$2:$I$698,$J13)=0,"Hanya di SO",IF(COUNTIF('Data SO'!$H$2:$H$1085,$J13)=0,"Hanya di SCM",IF(AND(ABS(E13)<0.01,ABS(H13)<1),"Sama",IF(ABS(E13)<0.01,"Selisih nominal",IF(ABS(H13)<1,"Selisih qty","Selisih qty & nominal"))))) -> Selisih qty & nominal | J13: crystaljelly5kg | K13: =IFERROR(INDEX('Data SCM'!$D$2:$D$698,MATCH($J13,'Data SCM'!$I$2:$I$698,0)),"") -> KG | L13: =IF(OR(AND(K13="GR",LOWER(B13)="kg"),AND(K13="ML",LOWER(B13)="liter")),0.001,1) -> 1 | M13: yang betul stok 80
... A35: =IFERROR(INDEX('Data SO'!$C$2:$C$1085,MATCH($J35,'Data SO'!$H$2:$H$1085,0)),INDEX('Data SCM'!$B$2:$B$698,MATCH($J35,'Data SCM'!$I$2:$I$698,0))) -> Lilin Kriting @1x100 pack | B35: =IFERROR(INDEX('Data SO'!$D$2:$D$1085,MATCH($J35,'Data SO'!$H$2:$H$1085,0)),K35) -> Pcs | C35: =SUMIF('Data SO'!$H$2:$H$1085,$J35,'Data SO'!$F$2:$F$1085) -> 1800 | D35: =SUMIF('Data SCM'!$I$2:$I$698,$J35,'Data SCM'!$E$2:$E$698)*L35 -> 0 | E35: =D35-C35 -> -1800 | F35: =SUMIF('Data SO'!$H$2:$H$1085,$J35,'Data SO'!$G$2:$G$1085) -> 1500000 | G35: =SUMIF('Data SCM'!$I$2:$I$698,$J35,'Data SCM'!$H$2:$H$698) -> 0 | H35: =G35-F35 -> -1500000 | I35: =IF(COUNTIF('Data SCM'!$I$2:$I$698,$J35)=0,"Hanya di SO",IF(COUNTIF('Data SO'!$H$2:$H$1085,$J35)=0,"Hanya di SCM",IF(AND(ABS(E35)<0.01,ABS(H35)<1),"Sama",IF(ABS(E35)<0.01,"Selisih nominal",IF(ABS(H35)<1,"Selisih qty","Selisih qty & nominal"))))) -> Hanya di SO | J35: lilinkriting1x100pack | K35: =IFERROR(INDEX('Data SCM'!$D$2:$D$698,MATCH($J35,'Data SCM'!$I$2:$I$698,0)),"") | L35: =IF(OR(AND(K35="GR",LOWER(B35)="kg"),AND(K35="ML",LOWER(B35)="liter")),0.001,1) -> 1 | M35: ini sama dengan lilin kriting hijau (belum ke edit nama barang nya)
A36: =IFERROR(INDEX('Data SO'!$C$2:$C$1085,MATCH($J36,'Data SO'!$H$2:$H$1085,0)),INDEX('Data SCM'!$B$2:$B$698,MATCH($J36,'Data SCM'!$I$2:$I$698,0))) -> Lilin Kriting Hijau @1X100 Pack | B36: =IFERROR(INDEX('Data SO'!$D$2:$D$1085,MATCH($J36,'Data SO'!$H$2:$H$1085,0)),K36) -> PCS | C36: =SUMIF('Data SO'!$H$2:$H$1085,$J36,'Data SO'!$F$2:$F$1085) -> 0 | D36: =SUMIF('Data SCM'!$I$2:$I$698,$J36,'Data SCM'!$E$2:$E$698)*L36 -> 300 | E36: =D36-C36 -> 300 | F36: =SUMIF('Data SO'!$H$2:$H$1085,$J36,'Data SO'!$G$2:$G$1085) -> 0 | G36: =SUMIF('Data SCM'!$I$2:$I$698,$J36,'Data SCM'!$H$2:$H$698) -> 1500000 | H36: =G36-F36 -> 1500000 | I36: =IF(COUNTIF('Data SCM'!$I$2:$I$698,$J36)=0,"Hanya di SO",IF(COUNTIF('Data SO'!$H$2:$H$1085,$J36)=0,"Hanya di SCM",IF(AND(ABS(E36)<0.01,ABS(H36)<1),"Sama",IF(ABS(E36)<0.01,"Selisih nominal",IF(ABS(H36)<1,"Selisih qty","Selisih qty & nominal"))))) -> Hanya di SCM | J36: lilinkritinghijau1x100pack | K36: =IFERROR(INDEX('Data SCM'!$D$2:$D$698,MATCH($J36,'Data SCM'!$I$2:$I$698,0)),"") -> PCS | L36: =IF(OR(AND(K36="GR",LOWER(B36)="kg"),AND(K36="ML",LOWER(B36)="liter")),0.001,1) -> 1
A37: =IFERROR(INDEX('Data SO'!$C$2:$C$1085,MATCH($J37,'Data SO'!$H$2:$H$1085,0)),INDEX('Data SCM'!$B$2:$B$698,MATCH($J37,'Data SCM'!$I$2:$I$698,0))) -> PEWARNA CROSS ROYAL BLUE @450ML | B37: =IFERROR(INDEX('Data SO'!$D$2:$D$1085,MATCH($J37,'Data SO'!$H$2:$H$1085,0)),K37) -> ml | C37: =SUMIF('Data SO'!$H$2:$H$1085,$J37,'Data SO'!$F$2:$F$1085) -> 0 | D37: =SUMIF('Data SCM'!$I$2:$I$698,$J37,'Data SCM'!$E$2:$E$698)*L37 -> 2250 | E37: =D37-C37 -> 2250 | F37: =SUMIF('Data SO'!$H$2:$H$1085,$J37,'Data SO'!$G$2:$G$1085) -> 0 | G37: =SUMIF('Data SCM'!$I$2:$I$698,$J37,'Data SCM'!$H$2:$H$698) -> 1387500.1 | H37: =G37-F37 -> 1387500.1 | I37: =IF(COUNTIF('Data SCM'!$I$2:$I$698,$J37)=0,"Hanya di SO",IF(COUNTIF('Data SO'!$H$2:$H$1085,$J37)=0,"Hanya di SCM",IF(AND(ABS(E37)<0.01,ABS(H37)<1),"Sama",IF(ABS(E37)<0.01,"Selisih nominal",IF(ABS(H37)<1,"Selisih qty","Selisih qty & nominal"))))) -> Selisih qty & nominal | J37: pewarnacrossroyalblue450ml | K37: =IFERROR(INDEX('Data SCM'!$D$2:$D$698,MATCH($J37,'Data SCM'!$I$2:$I$698,0)),"") -> ML | L37: =IF(OR(AND(K37="GR",LOWER(B37)="kg"),AND(K37="ML",LOWER(B37)="liter")),0.001,1) -> 1 | M37: yang betul stok 0 yang ukuran 450 ml
A38: =IFERROR(INDEX('Data SO'!$C$2:$C$1085,MATCH($J38,'Data SO'!$H$2:$H$1085,0)),INDEX('Data SCM'!$B$2:$B$698,MATCH($J38,'Data SCM'!$I$2:$I$698,0))) -> Lilin Spiral Pendek Rainbow @1x50 Pack | B38: =IFERROR(INDEX('Data SO'!$D$2:$D$1085,MATCH($J38,'Data SO'!$H$2:$H$1085,0)),K38) -> Pcs | C38: =SUMIF('Data SO'!$H$2:$H$1085,$J38,'Data SO'!$F$2:$F$1085) -> 2410 | D38: =SUMIF('Data SCM'!$I$2:$I$698,$J38,'Data SCM'!$E$2:$E$698)*L38 -> 241 | E38: =D38-C38 -> -2169 | F38: =SUMIF('Data SO'!$H$2:$H$1085,$J38,'Data SO'!$G$2:$G$1085) -> 1446000 | G38: =SUMIF('Data SCM'!$I$2:$I$698,$J38,'Data SCM'!$H$2:$H$698) -> 144600 | H38: =G38-F38 -> -1301400 | I38: =IF(COUNTIF('Data SCM'!$I$2:$I$698,$J38)=0,"Hanya di SO",IF(COUNTIF('Data SO'!$H$2:$H$1085,$J38)=0,"Hanya di SCM",IF(AND(ABS(E38)<0.01,ABS(H38)<1),"Sama",IF(ABS(E38)<0.01,"Selisih nominal",IF(ABS(H38)<1,"Selisih qty","Selisih qty & nominal"))))) -> Selisih qty & nominal | J38: lilinspiralpendekrainbow1x50pack | K38: =IFERROR(INDEX('Data SCM'!$D$2:$D$698,MATCH($J38,'Data SCM'!$I$2:$I$698,0)),"") -> PCS | L38: =IF(OR(AND(K38="GR",LOWER(B38)="kg"),AND(K38="ML",LOWER(B38)="liter")),0.001,1) -> 1 | M38: yang betul 2400 pcs harga 600 atau sama dengan 240 pak harga 6000
A39: =IFERROR(INDEX('Data SO'!$C$2:$C$1085,MATCH($J39,'Data SO'!$H$2:$H$1085,0)),INDEX('Data SCM'!$B$2:$B$698,MATCH($J39,'Data SCM'!$I$2:$I$698,0))) -> Lilin Spiral Pendek Red @1x50 Pack | B39: =IFERROR(INDEX('Data SO'!$D$2:$D$1085,MATCH($J39,'Data SO'!$H$2:$H$1085,0)),K39) -> Pcs | C39: =SUMIF('Data SO'!$H$2:$H$1085,$J39,'Data SO'!$F$2:$F$1085) -> 2290 | D39: =SUMIF('Data SCM'!$I$2:$I$698,$J39,'Data SCM'!$E$2:$E$698)*L39 -> 229 | E39: =D39-C39 -> -2061 | F39: =SUMIF('Data SO'!$H$2:$H$1085,$J39,'Data SO'!$G$2:$G$1085) -> 1374000 | G39: =SUMIF('Data SCM'!$I$2:$I$698,$J39,'Data SCM'!$H$2:$H$698) -> 137400 | H39: =G39-F39 -> -1236600 | I39: =IF(COUNTIF('Data SCM'!$I$2:$I$698,$J39)=0,"Hanya di SO",IF(COUNTIF('Data SO'!$H$2:$H$1085,$J39)=0,"Hanya di SCM",IF(AND(ABS(E39)<0.01,ABS(H39)<1),"Sama",IF(ABS(E39)<0.01,"Selisih nominal",IF(ABS(H39)<1,"Selisih qty","Selisih qty & nominal"))))) -> Selisih qty & nominal | J39: lilinspiralpendekred1x50pack | K39: =IFERROR(INDEX('Data SCM'!$D$2:$D$698,MATCH($J39,'Data SCM'!$I$2:$I$698,0)),"") -> PCS | L39: =IF(OR(AND(K39="GR",LOWER(B39)="kg"),AND(K39="ML",LOWER(B39)="liter")),0.001,1) -> 1 | M39: yang betul 2290 pcs harga 600 atau sama dengan 229 pak harga 6000
A40: =IFERROR(INDEX('Data SO'!$C$2:$C$1085,MATCH($J40,'Data SO'!$H$2:$H$1085,0)),INDEX('Data SCM'!$B$2:$B$698,MATCH($J40,'Data SCM'!$I$2:$I$698,0))) -> Plastik Roti Tawar Vol 11 | B40: =IFERROR(INDEX('Data SO'!$D$2:$D$1085,MATCH($J40,'Data SO'!$H$2:$H$1085,0)),K40) -> Pcs | C40: =SUMIF('Data SO'!$H$2:$H$1085,$J40,'Data SO'!$F$2:$F$1085) -> 0 | D40: =SUMIF('Data SCM'!$I$2:$I$698,$J40,'Data SCM'!$E$2:$E$698)*L40 -> 1400 | E40: =D40-C40 -> 1400 | F40: =SUMIF('Data SO'!$H$2:$H$1085,$J40,'Data SO'!$G$2:$G$1085) -> 0 | G40: =SUMIF('Data SCM'!$I$2:$I$698,$J40,'Data SCM'!$H$2:$H$698) -> 1234800 | H40: =G40-F40 -> 1234800 | I40: =IF(COUNTIF('Data SCM'!$I$2:$I$698,$J40)=0,"Hanya di SO",IF(COUNTIF('Data SO'!$H$2:$H$1085,$J40)=0,"Hanya di SCM",IF(AND(ABS(E40)<0.01,ABS(H40)<1),"Sama",IF(ABS(E40)<0.01,"Selisih nominal",IF(ABS(H40)<1,"Selisih qty","Selisih qty & nominal"))))) -> Selisih qty & nominal | J40: plastikrotitawarvol11 | K40: =IFERROR(INDEX('Data SCM'!$D$2:$D$698,MATCH($J40,'Data SCM'!$I$2:$I$698,0)),"") -> PCS | L40: =IF(OR(AND(K40="GR",LOWER(B40)="kg"),AND(K40="ML",LOWER(B40)="liter")),0.001,1) -> 1 | M40: yang betul 1400
A41: =IFERROR(INDEX('Data SO'!$C$2:$C$1085,MATCH($J41,'Data SO'!$H$2:$H$1085,0)),INDEX('Data SCM'!$B$2:$B$698,MATCH($J41,'Data SCM'!$I$2:$I$698,0))) -> Backround Angry Bird | B41: =IFERROR(INDEX('Data SO'!$D$2:$D$1085,MATCH($J41,'Data SO'!$H$2:$H$1085,0)),K41) -> Pcs | C41: =SUMIF('Data SO'!$H$2:$H$1085,$J41,'Data SO'!$F$2:$F$1085) -> 129 | D41: =SUMIF('Data SCM'!$I$2:$I$698,$J41,'Data SCM'!$E$2:$E$698)*L41 -> 0 | E41: =D41-C41 -> -129 | F41: =SUMIF('Data SO'!$H$2:$H$1085,$J41,'Data SO'!$G$2:$G$1085) -> 1096500 | G41: =SUMIF('Data SCM'!$I$2:$I$698,$J41,'Data SCM'!$H$2:$H$698) -> 0 | H41: =G41-F41 -> -1096500 | I41: =IF(COUNTIF('Data SCM'!$I$2:$I$698,$J41)=0,"Hanya di SO",IF(COUNTIF('Data SO'!$H$2:$H$1085,$J41)=0,"Hanya di SCM",IF(AND(ABS(E41)<0.01,ABS(H41)<1),"Sama",IF(ABS(E41)<0.01,"Selisih nominal",IF(ABS(H41)<1,"Selisih qty","Selisih qty & nominal"))))) -> Selisih qty & nominal | J41: backroundangrybird | K41: =IFERROR(INDEX('Data SCM'!$D$2:$D$698,MATCH($J41,'Data SCM'!$I$2:$I$698,0)),"") -> PCS | L41: =IF(OR(AND(K41="GR",LOWER(B41)="kg"),AND(K41="ML",LOWER(B41)="liter")),0.001,1) -> 1 | M41: yang betul 129 (deadstok)
A42: =IFERROR(INDEX('Data SO'!$C$2:$C$1085,MATCH($J42,'Data SO'!$H$2:$H$1085,0)),INDEX('Data SCM'!$B$2:$B$698,MATCH($J42,'Data SCM'!$I$2:$I$698,0))) -> Lilin Spiral Pendek Green @1x50 Pack | B42: =IFERROR(INDEX('Data SO'!$D$2:$D$1085,MATCH($J42,'Data SO'!$H$2:$H$1085,0)),K42) -> Pcs | C42: =SUMIF('Data SO'!$H$2:$H$1085,$J42,'Data SO'!$F$2:$F$1085) -> 2000 | D42: =SUMIF('Data SCM'!$I$2:$I$698,$J42,'Data SCM'!$E$2:$E$698)*L42 -> 200 | E42: =D42-C42 -> -1800 | F42: =SUMIF('Data SO'!$H$2:$H$1085,$J42,'Data SO'!$G$2:$G$1085) -> 1200000 | G42: =SUMIF('Data SCM'!$I$2:$I$698,$J42,'Data SCM'!$H$2:$H$698) -> 120000 | H42: =G42-F42 -> -1080000 | I42: =IF(COUNTIF('Data SCM'!$I$2:$I$698,$J42)=0,"Hanya di SO",IF(COUNTIF('Data SO'!$H$2:$H$1085,$J42)=0,"Hanya di SCM",IF(AND(ABS(E42)<0.01,ABS(H42)<1),"Sama",IF(ABS(E42)<0.01,"Selisih nominal",IF(ABS(H42)<1,"Selisih qty","Selisih qty & nominal"))))) -> Selisih qty & nominal | J42: lilinspiralpendekgreen1x50pack | K42: =IFERROR(INDEX('Data SCM'!$D$2:$D$698,MATCH($J42,'Data SCM'!$I$2:$I$698,0)),"") -> PCS | L42: =IF(OR(AND(K42="GR",LOWER(B42)="kg"),AND(K42="ML",LOWER(B42)="liter")),0.001,1) -> 1 | M42: yang betul 2000 pcs harga 600 atau sama dengan 200 pak harga 6000
A43: =IFERROR(INDEX('Data SO'!$C$2:$C$1085,MATCH($J43,'Data SO'!$H$2:$H$1085,0)),INDEX('Data SCM'!$B$2:$B$698,MATCH($J43,'Data SCM'!$I$2:$I$698,0))) -> Red Handsoap 5Liter | B43: =IFERROR(INDEX('Data SO'!$D$2:$D$1085,MATCH($J43,'Data SO'!$H$2:$H$1085,0)),K43) -> liter | C43: =SUMIF('Data SO'!$H$2:$H$1085,$J43,'Data SO'!$F$2:$F$1085) -> 90 | D43: =SUMIF('Data SCM'!$I$2:$I$698,$J43,'Data SCM'!$E$2:$E$698)*L43 -> 0 | E43: =D43-C43 -> -90 | F43: =SUMIF('Data SO'!$H$2:$H$1085,$J43,'Data SO'!$G$2:$G$1085) -> 990000 | G43: =SUMIF('Data SCM'!$I$2:$I$698,$J43,'Data SCM'!$H$2:$H$698) -> 0 | H43: =G43-F43 -> -990000 | I43: =IF(COUNTIF('Data SCM'!$I$2:$I$698,$J43)=0,"Hanya di SO",IF(COUNTIF('Data SO'!$H$2:$H$1085,$J43)=0,"Hanya di SCM",IF(AND(ABS(E43)<0.01,ABS(H43)<1),"Sama",IF(ABS(E43)<0.01,"Selisih nominal",IF(ABS(H43)<1,"Selisih qty","Selisih qty & nominal"))))) -> Selisih qty & nominal | J43: redhandsoap5liter | K43: =IFERROR(INDEX('Data SCM'!$D$2:$D$698,MATCH($J43,'Data SCM'!$I$2:$I$698,0)),"") -> ML | L43: =IF(OR(AND(K43="GR",LOWER(B43)="kg"),AND(K43="ML",LOWER(B43)="liter")),0.001,1) -> 0.001 | M43: yang betul red hand soap 90 di sistem ke hadwash jasmine
A44: =IFERROR(INDEX('Data SO'!$C$2:$C$1085,MATCH($J44,'Data SO'!$H$2:$H$1085,0)),INDEX('Data SCM'!$B$2:$B$698,MATCH($J44,'Data SCM'!$I$2:$I$698,0))) -> Dus Mochi Oreo Spesial | B44: =IFERROR(INDEX('Data SO'!$D$2:$D$1085,MATCH($J44,'Data SO'!$H$2:$H$1085,0)),K44) -> Pcs | C44: =SUMIF('Data SO'!$H$2:$H$1085,$J44,'Data SO'!$F$2:$F$1085) -> 800 | D44: =SUMIF('Data SCM'!$I$2:$I$698,$J44,'Data SCM'!$E$2:$E$698)*L44 -> 0 | E44: =D44-C44 -> -800 | F44: =SUMIF('Data SO'!$H$2:$H$1085,$J44,'Data SO'!$G$2:$G$1085) -> 980000 | G44: =SUMIF('Data SCM'!$I$2:$I$698,$J44,'Data SCM'!$H$2:$H$698) -> 0 | H44: =G44-F44 -> -980000 | I44: =IF(COUNTIF('Data SCM'!$I$2:$I$698,$J44)=0,"Hanya di SO",IF(COUNTIF('Data SO'!$H$2:$H$1085,$J44)=0,"Hanya di SCM",IF(AND(ABS(E44)<0.01,ABS(H44)<1),"Sama",IF(ABS(E44)<0.01,"Selisih nominal",IF(ABS(H44)<1,"Selisih qty","Selisih qty & nominal"))))) -> Selisih qty & nominal | J44: dusmochioreospesial | K44: =IFERROR(INDEX('Data SCM'!$D$2:$D$698,MATCH($J44,'Data SCM'!$I$2:$I$698,0)),"") -> PCS | L44: =IF(OR(AND(K44="GR",LOWER(B44)="kg"),AND(K44="ML",LOWER(B44)="liter")),0.001,1) -> 1 | M44: yang betul 800 (deadstok)
A45: =IFERROR(INDEX('Data SO'!$C$2:$C$1085,MATCH($J45,'Data SO'!$H$2:$H$1085,0)),INDEX('Data SCM'!$B$2:$B$698,MATCH($J45,'Data SCM'!$I$2:$I$698,0))) -> Sticker Dubai Chewy Cookies Besar | B45: =IFERROR(INDEX('Data SO'!$D$2:$D$1085,MATCH($J45,'Data SO'!$H$2:$H$1085,0)),K45) -> PCS | C45: =SUMIF('Data SO'!$H$2:$H$1085,$J45,'Data SO'!$F$2:$F$1085) -> 0 | D45: =SUMIF('Data SCM'!$I$2:$I$698,$J45,'Data SCM'!$E$2:$E$698)*L45 -> 1450 | E45: =D45-C45 -> 1450 | F45: =SUMIF('Data SO'!$H$2:$H$1085,$J45,'Data SO'!$G$2:$G$1085) -> 0 | G45: =SUMIF('Data SCM'!$I$2:$I$698,$J45,'Data SCM'!$H$2:$H$698) -> 966666.71 | H45: =G45-F45 -> 966666.71 | I45: =IF(COUNTIF('Data SCM'!$I$2:$I$698,$J45)=0,"Hanya di SO",IF(COUNTIF('Data SO'!$H$2:$H$1085,$J45)=0,"Hanya di SCM",IF(AND(ABS(E45)<0.01,ABS(H45)<1),"Sama",IF(ABS(E45)<0.01,"Selisih nominal",IF(ABS(H45)<1,"Selisih qty","Selisih qty & nominal"))))) -> Hanya di SCM | J45: stickerdubaichewycookiesbesar | K45: =IFERROR(INDEX('Data SCM'!$D$2:$D$698,MATCH($J45,'Data SCM'!$I$2:$I$698,0)),"") -> PCS | L45: =IF(OR(AND(K45="GR",LOWER(B45)="kg"),AND(K45="ML",LOWER(B45)="liter")),0.001,1) -> 1 | M45: yang betul 0
A46: =IFERROR(INDEX('Data SO'!$C$2:$C$1085,MATCH($J46,'Data SO'!$H$2:$H$1085,0)),INDEX('Data SCM'!$B$2:$B$698,MATCH($J46,'Data SCM'!$I$2:$I$698,0))) -> PATUNG DORA | B46: =IFERROR(INDEX('Data SO'!$D$2:$D$1085,MATCH($J46,'Data SO'!$H$2:$H$1085,0)),K46) -> Pcs | C46: =SUMIF('Data SO'!$H$2:$H$1085,$J46,'Data SO'!$F$2:$F$1085) -> 161 | D46: =SUMIF('Data SCM'!$I$2:$I$698,$J46,'Data SCM'!$E$2:$E$698)*L46 -> 0 | E46: =D46-C46 -> -161 | F46: =SUMIF('Data SO'!$H$2:$H$1085,$J46,'Data SO'!$G$2:$G$1085) -> 966000 | G46: =SUMIF('Data SCM'!$I$2:$I$698,$J46,'Data SCM'!$H$2:$H$698) -> 0 | H46: =G46-F46 -> -966000 | I46: =IF(COUNTIF('Data SCM'!$I$2:$I$698,$J46)=0,"Hanya di SO",IF(COUNTIF('Data SO'!$H$2:$H$1085,$J46)=0,"Hanya di SCM",IF(AND(ABS(E46)<0.01,ABS(H46)<1),"Sama",IF(ABS(E46)<0.01,"Selisih nominal",IF(ABS(H46)<1,"Selisih qty","Selisih qty & nominal"))))) -> Hanya di SO | J46: patungdora | K46: =IFERROR(INDEX('Data SCM'!$D$2:$D$698,MATCH($J46,'Data SCM'!$I$2:$I$698,0)),"") | L46: =IF(OR(AND(K46="GR",LOWER(B46)="kg"),AND(K46="ML",LOWER(B46)="liter")),0.001,1) -> 1 | M46: yang betul 161 (deadstok)
A47: =IFERROR(INDEX('Data SO'!$C$2:$C$1085,MATCH($J47,'Data SO'!$H$2:$H$1085,0)),INDEX('Data SCM'!$B$2:$B$698,MATCH($J47,'Data SCM'!$I$2:$I$698,0))) -> Lilin Spiral Pendek Rosegold @1x50 Pack | B47: =IFERROR(INDEX('Data SO'!$D$2:$D$1085,MATCH($J47,'Data SO'!$H$2:$H$1085,0)),K47) -> Pcs | C47: =SUMIF('Data SO'!$H$2:$H$1085,$J47,'Data SO'!$F$2:$F$1085) -> 1500 | D47: =SUMIF('Data SCM'!$I$2:$I$698,$J47,'Data SCM'!$E$2:$E$698)*L47 -> 150 | E47: =D47-C47 -> -1350 | F47: =SUMIF('Data SO'!$H$2:$H$1085,$J47,'Data SO'!$G$2:$G$1085) -> 900000 | G47: =SUMIF('Data SCM'!$I$2:$I$698,$J47,'Data SCM'!$H$2:$H$698) -> 90000 | H47: =G47-F47 -> -810000 | I47: =IF(COUNTIF('Data SCM'!$I$2:$I$698,$J47)=0,"Hanya di SO",IF(COUNTIF('Data SO'!$H$2:$H$1085,$J47)=0,"Hanya di SCM",IF(AND(ABS(E47)<0.01,ABS(H47)<1),"Sama",IF(ABS(E47)<0.01,"Selisih nominal",IF(ABS(H47)<1,"Selisih qty","Selisih qty & nominal"))))) -> Selisih qty & nominal | J47: lilinspiralpendekrosegold1x50pack | K47: =IFERROR(INDEX('Data SCM'!$D$2:$D$698,MATCH($J47,'Data SCM'!$I$2:$I$698,0)),"") -> PCS | L47: =IF(OR(AND(K47="GR",LOWER(B47)="kg"),AND(K47="ML",LOWER(B47)="liter")),0.001,1) -> 1 | M47: yang betul 1500 pcs harga 600 atau sama dengan 150 pak harga 6000
A48: =IFERROR(INDEX('Data SO'!$C$2:$C$1085,MATCH($J48,'Data SO'!$H$2:$H$1085,0)),INDEX('Data SCM'!$B$2:$B$698,MATCH($J48,'Data SCM'!$I$2:$I$698,0))) -> Backround Kecil Princess | B48: =IFERROR(INDEX('Data SO'!$D$2:$D$1085,MATCH($J48,'Data SO'!$H$2:$H$1085,0)),K48) -> Pcs | C48: =SUMIF('Data SO'!$H$2:$H$1085,$J48,'Data SO'!$F$2:$F$1085) -> 175 | D48: =SUMIF('Data SCM'!$I$2:$I$698,$J48,'Data SCM'!$E$2:$E$698)*L48 -> 0 | E48: =D48-C48 -> -175 | F48: =SUMIF('Data SO'!$H$2:$H$1085,$J48,'Data SO'!$G$2:$G$1085) -> 787500 | G48: =SUMIF('Data SCM'!$I$2:$I$698,$J48,'Data SCM'!$H$2:$H$698) -> 0 | H48: =G48-F48 -> -787500 | I48: =IF(COUNTIF('Data SCM'!$I$2:$I$698,$J48)=0,"Hanya di SO",IF(COUNTIF('Data SO'!$H$2:$H$1085,$J48)=0,"Hanya di SCM",IF(AND(ABS(E48)<0.01,ABS(H48)<1),"Sama",IF(ABS(E48)<0.01,"Selisih nominal",IF(ABS(H48)<1,"Selisih qty","Selisih qty & nominal"))))) -> Selisih qty & nominal | J48: backroundkecilprincess | K48: =IFERROR(INDEX('Data SCM'!$D$2:$D$698,MATCH($J48,'Data SCM'!$I$2:$I$698,0)),"") -> PCS | L48: =IF(OR(AND(K48="GR",LOWER(B48)="kg"),AND(K48="ML",LOWER(B48)="liter")),0.001,1) -> 1 | M48: yang betul 175 (deadstok)
... A128: =IFERROR(INDEX('Data SO'!$C$2:$C$1085,MATCH($J128,'Data SO'!$H$2:$H$1085,0)),INDEX('Data SCM'!$B$2:$B$698,MATCH($J128,'Data SCM'!$I$2:$I$698,0))) -> Nevada Mauripan | B128: =IFERROR(INDEX('Data SO'!$D$2:$D$1085,MATCH($J128,'Data SO'!$H$2:$H$1085,0)),K128) -> PCS | C128: =SUMIF('Data SO'!$H$2:$H$1085,$J128,'Data SO'!$F$2:$F$1085) -> 0 | D128: =SUMIF('Data SCM'!$I$2:$I$698,$J128,'Data SCM'!$E$2:$E$698)*L128 -> 2 | E128: =D128-C128 -> 2 | F128: =SUMIF('Data SO'!$H$2:$H$1085,$J128,'Data SO'!$G$2:$G$1085) -> 0 | G128: =SUMIF('Data SCM'!$I$2:$I$698,$J128,'Data SCM'!$H$2:$H$698) -> 2 | H128: =G128-F128 -> 2 | I128: =IF(COUNTIF('Data SCM'!$I$2:$I$698,$J128)=0,"Hanya di SO",IF(COUNTIF('Data SO'!$H$2:$H$1085,$J128)=0,"Hanya di SCM",IF(AND(ABS(E128)<0.01,ABS(H128)<1),"Sama",IF(ABS(E128)<0.01,"Selisih nominal",IF(ABS(H128)<1,"Selisih qty","Selisih qty & nominal"))))) -> Hanya di SCM | J128: nevadamauripan | K128: =IFERROR(INDEX('Data SCM'!$D$2:$D$698,MATCH($J128,'Data SCM'!$I$2:$I$698,0)),"") -> PCS | L128: =IF(OR(AND(K128="GR",LOWER(B128)="kg"),AND(K128="ML",LOWER(B128)="liter")),0.001,1) -> 1 | M128: yang betul stok 2 diinput di mauripan di so nominal
A129: =IFERROR(INDEX('Data SO'!$C$2:$C$1085,MATCH($J129,'Data SO'!$H$2:$H$1085,0)),INDEX('Data SCM'!$B$2:$B$698,MATCH($J129,'Data SCM'!$I$2:$I$698,0))) -> Zee Strawberry | B129: =IFERROR(INDEX('Data SO'!$D$2:$D$1085,MATCH($J129,'Data SO'!$H$2:$H$1085,0)),K129) -> gram | C129: =SUMIF('Data SO'!$H$2:$H$1085,$J129,'Data SO'!$F$2:$F$1085) -> 14280 | D129: =SUMIF('Data SCM'!$I$2:$I$698,$J129,'Data SCM'!$E$2:$E$698)*L129 -> 14280 | E129: =D129-C129 -> 0 | F129: =SUMIF('Data SO'!$H$2:$H$1085,$J129,'Data SO'!$G$2:$G$1085) -> 2268000 | G129: =SUMIF('Data SCM'!$I$2:$I$698,$J129,'Data SCM'!$H$2:$H$698) -> 2267999.6 | H129: =G129-F129 -> -0.42 | I129: =IF(COUNTIF('Data SCM'!$I$2:$I$698,$J129)=0,"Hanya di SO",IF(COUNTIF('Data SO'!$H$2:$H$1085,$J129)=0,"Hanya di SCM",IF(AND(ABS(E129)<0.01,ABS(H129)<1),"Sama",IF(ABS(E129)<0.01,"Selisih nominal",IF(ABS(H129)<1,"Selisih qty","Selisih qty & nominal"))))) -> Sama | J129: zeestrawberry | K129: =IFERROR(INDEX('Data SCM'!$D$2:$D$698,MATCH($J129,'Data SCM'!$I$2:$I$698,0)),"") -> GR | L129: =IF(OR(AND(K129="GR",LOWER(B129)="kg"),AND(K129="ML",LOWER(B129)="liter")),0.001,1) -> 1
A130: =IFERROR(INDEX('Data SO'!$C$2:$C$1085,MATCH($J130,'Data SO'!$H$2:$H$1085,0)),INDEX('Data SCM'!$B$2:$B$698,MATCH($J130,'Data SCM'!$I$2:$I$698,0))) -> Kresek Jumbo Uk 50 @50Pcs | B130: =IFERROR(INDEX('Data SO'!$D$2:$D$1085,MATCH($J130,'Data SO'!$H$2:$H$1085,0)),K130) -> kg | C130: =SUMIF('Data SO'!$H$2:$H$1085,$J130,'Data SO'!$F$2:$F$1085) -> 228 | D130: =SUMIF('Data SCM'!$I$2:$I$698,$J130,'Data SCM'!$E$2:$E$698)*L130 -> 6612 | E130: =D130-C130 -> 6384 | F130: =SUMIF('Data SO'!$H$2:$H$1085,$J130,'Data SO'!$G$2:$G$1085) -> 9006000 | G130: =SUMIF('Data SCM'!$I$2:$I$698,$J130,'Data SCM'!$H$2:$H$698) -> 9006000.2 | H130: =G130-F130 -> 0.228 | I130: =IF(COUNTIF('Data SCM'!$I$2:$I$698,$J130)=0,"Hanya di SO",IF(COUNTIF('Data SO'!$H$2:$H$1085,$J130)=0,"Hanya di SCM",IF(AND(ABS(E130)<0.01,ABS(H130)<1),"Sama",IF(ABS(E130)<0.01,"Selisih nominal",IF(ABS(H130)<1,"Selisih qty","Selisih qty & nominal"))))) -> Selisih qty | J130: kresekjumbouk5050pcs | K130: =IFERROR(INDEX('Data SCM'!$D$2:$D$698,MATCH($J130,'Data SCM'!$I$2:$I$698,0)),"") -> PCS | L130: =IF(OR(AND(K130="GR",LOWER(B130)="kg"),AND(K130="ML",LOWER(B130)="liter")),0.001,1) -> 1 | M130: yang betul 228 kg
A131: =IFERROR(INDEX('Data SO'!$C$2:$C$1085,MATCH($J131,'Data SO'!$H$2:$H$1085,0)),INDEX('Data SCM'!$B$2:$B$698,MATCH($J131,'Data SCM'!$I$2:$I$698,0))) -> Tatakan 22X22 Kotak | B131: =IFERROR(INDEX('Data SO'!$D$2:$D$1085,MATCH($J131,'Data SO'!$H$2:$H$1085,0)),K131) -> pcs | C131: =SUMIF('Data SO'!$H$2:$H$1085,$J131,'Data SO'!$F$2:$F$1085) -> 2820 | D131: =SUMIF('Data SCM'!$I$2:$I$698,$J131,'Data SCM'!$E$2:$E$698)*L131 -> 2820 | E131: =D131-C131 -> 0 | F131: =SUMIF('Data SO'!$H$2:$H$1085,$J131,'Data SO'!$G$2:$G$1085) -> 3995000 | G131: =SUMIF('Data SCM'!$I$2:$I$698,$J131,'Data SCM'!$H$2:$H$698) -> 3995000.1 | H131: =G131-F131 -> 0.094 | I131: =IF(COUNTIF('Data SCM'!$I$2:$I$698,$J131)=0,"Hanya di SO",IF(COUNTIF('Data SO'!$H$2:$H$1085,$J131)=0,"Hanya di SCM",IF(AND(ABS(E131)<0.01,ABS(H131)<1),"Sama",IF(ABS(E131)<0.01,"Selisih nominal",IF(ABS(H131)<1,"Selisih qty","Selisih qty & nominal"))))) -> Sama | J131: tatakan22x22kotak | K131: =IFERROR(INDEX('Data SCM'!$D$2:$D$698,MATCH($J131,'Data SCM'!$I$2:$I$698,0)),"") -> PCS | L131: =IF(OR(AND(K131="GR",LOWER(B131)="kg"),AND(K131="ML",LOWER(B131)="liter")),0.001,1) -> 1
A132: =IFERROR(INDEX('Data SO'!$C$2:$C$1085,MATCH($J132,'Data SO'!$H$2:$H$1085,0)),INDEX('Data SCM'!$B$2:$B$698,MATCH($J132,'Data SCM'!$I$2:$I$698,0))) -> Tatakan 28X28 Kotak | B132: =IFERROR(INDEX('Data SO'!$D$2:$D$1085,MATCH($J132,'Data SO'!$H$2:$H$1085,0)),K132) -> pcs | C132: =SUMIF('Data SO'!$H$2:$H$1085,$J132,'Data SO'!$F$2:$F$1085) -> 2460 | D132: =SUMIF('Data SCM'!$I$2:$I$698,$J132,'Data SCM'!$E$2:$E$698)*L132 -> 2460 | E132: =D132-C132 -> 0 | F132: =SUMIF('Data SO'!$H$2:$H$1085,$J132,'Data SO'!$G$2:$G$1085) -> 4715000 | G132: =SUMIF('Data SCM'!$I$2:$I$698,$J132,'Data SCM'!$H$2:$H$698) -> 4715000.1 | H132: =G132-F132 -> 0.082 | I132: =IF(COUNTIF('Data SCM'!$I$2:$I$698,$J132)=0,"Hanya di SO",IF(COUNTIF('Data SO'!$H$2:$H$1085,$J132)=0,"Hanya di SCM",IF(AND(ABS(E132)<0.01,ABS(H132)<1),"Sama",IF(ABS(E132)<0.01,"Selisih nominal",IF(ABS(H132)<1,"Selisih qty","Selisih qty & nominal"))))) -> Sama | J132: tatakan28x28kotak | K132: =IFERROR(INDEX('Data SCM'!$D$2:$D$698,MATCH($J132,'Data SCM'!$I$2:$I$698,0)),"") -> PCS | L132: =IF(OR(AND(K132="GR",LOWER(B132)="kg"),AND(K132="ML",LOWER(B132)="liter")),0.001,1) -> 1
A133: =IFERROR(INDEX('Data SO'!$C$2:$C$1085,MATCH($J133,'Data SO'!$H$2:$H$1085,0)),INDEX('Data SCM'!$B$2:$B$698,MATCH($J133,'Data SCM'!$I$2:$I$698,0))) -> Lilin Kriting silver @1x100 pack | B133: =IFERROR(INDEX('Data SO'!$D$2:$D$1085,MATCH($J133,'Data SO'!$H$2:$H$1085,0)),K133) -> pcs | C133: =SUMIF('Data SO'!$H$2:$H$1085,$J133,'Data SO'!$F$2:$F$1085) -> 1326 | D133: =SUMIF('Data SCM'!$I$2:$I$698,$J133,'Data SCM'!$E$2:$E$698)*L133 -> 1326 | E133: =D133-C133 -> 0 | F133: =SUMIF('Data SO'!$H$2:$H$1085,$J133,'Data SO'!$G$2:$G$1085) -> 1105000 | G133: =SUMIF('Data SCM'!$I$2:$I$698,$J133,'Data SCM'!$H$2:$H$698) -> 1105000 | H133: =G133-F133 -> -0.0442 | I133: =IF(COUNTIF('Data SCM'!$I$2:$I$698,$J133)=0,"Hanya di SO",IF(COUNTIF('Data SO'!$H$2:$H$1085,$J133)=0,"Hanya di SCM",IF(AND(ABS(E133)<0.01,ABS(H133)<1),"Sama",IF(ABS(E133)<0.01,"Selisih nominal",IF(ABS(H133)<1,"Selisih qty","Selisih qty & nominal"))))) -> Sama | J133: lilinkritingsilver1x100pack | K133: =IFERROR(INDEX('Data SCM'!$D$2:$D$698,MATCH($J133,'Data SCM'!$I$2:$I$698,0)),"") -> PCS | L133: =IF(OR(AND(K133="GR",LOWER(B133)="kg"),AND(K133="ML",LOWER(B133)="liter")),0.001,1) -> 1
A134: =IFERROR(INDEX('Data SO'!$C$2:$C$1085,MATCH($J134,'Data SO'!$H$2:$H$1085,0)),INDEX('Data SCM'!$B$2:$B$698,MATCH($J134,'Data SCM'!$I$2:$I$698,0))) -> Lilin Kriting gold @1x100 pack | B134: =IFERROR(INDEX('Data SO'!$D$2:$D$1085,MATCH($J134,'Data SO'!$H$2:$H$1085,0)),K134) -> pcs | C134: =SUMIF('Data SO'!$H$2:$H$1085,$J134,'Data SO'!$F$2:$F$1085) -> 1176 | D134: =SUMIF('Data SCM'!$I$2:$I$698,$J134,'Data SCM'!$E$2:$E$698)*L134 -> 1176 | E134: =D134-C134 -> 0 | F134: =SUMIF('Data SO'!$H$2:$H$1085,$J134,'Data SO'!$G$2:$G$1085) -> 980000 | G134: =SUMIF('Data SCM'!$I$2:$I$698,$J134,'Data SCM'!$H$2:$H$698) -> 979999.96 | H134: =G134-F134 -> -0.0392 | I134: =IF(COUNTIF('Data SCM'!$I$2:$I$698,$J134)=0,"Hanya di SO",IF(COUNTIF('Data SO'!$H$2:$H$1085,$J134)=0,"Hanya di SCM",IF(AND(ABS(E134)<0.01,ABS(H134)<1),"Sama",IF(ABS(E134)<0.01,"Selisih nominal",IF(ABS(H134)<1,"Selisih qty","Selisih qty & nominal"))))) -> Sama | J134: lilinkritinggold1x100pack | K134: =IFERROR(INDEX('Data SCM'!$D$2:$D$698,MATCH($J134,'Data SCM'!$I$2:$I$698,0)),"") -> PCS | L134: =IF(OR(AND(K134="GR",LOWER(B134)="kg"),AND(K134="ML",LOWER(B134)="liter")),0.001,1) -> 1
A135: =IFERROR(INDEX('Data SO'!$C$2:$C$1085,MATCH($J135,'Data SO'!$H$2:$H$1085,0)),INDEX('Data SCM'!$B$2:$B$698,MATCH($J135,'Data SCM'!$I$2:$I$698,0))) -> PEWARNA CROSS CHOCOLATE @450ML | B135: =IFERROR(INDEX('Data SO'!$D$2:$D$1085,MATCH($J135,'Data SO'!$H$2:$H$1085,0)),K135) -> ml | C135: =SUMIF('Data SO'!$H$2:$H$1085,$J135,'Data SO'!$F$2:$F$1085) -> 900 | D135: =SUMIF('Data SCM'!$I$2:$I$698,$J135,'Data SCM'!$E$2:$E$698)*L135 -> 900 | E135: =D135-C135 -> 0 | F135: =SUMIF('Data SO'!$H$2:$H$1085,$J135,'Data SO'!$G$2:$G$1085) -> 277500 | G135: =SUMIF('Data SCM'!$I$2:$I$698,$J135,'Data SCM'!$H$2:$H$698) -> 277499.97 | H135: =G135-F135 -> -0.03 | I135: =IF(COUNTIF('Data SCM'!$I$2:$I$698,$J135)=0,"Hanya di SO",IF(COUNTIF('Data SO'!$H$2:$H$1085,$J135)=0,"Hanya di SCM",IF(AND(ABS(E135)<0.01,ABS(H135)<1),"Sama",IF(ABS(E135)<0.01,"Selisih nominal",IF(ABS(H135)<1,"Selisih qty","Selisih qty & nominal"))))) -> Sama | J135: pewarnacrosschocolate450ml | K135: =IFERROR(INDEX('Data SCM'!$D$2:$D$698,MATCH($J135,'Data SCM'!$I$2:$I$698,0)),"") -> ML | L135: =IF(OR(AND(K135="GR",LOWER(B135)="kg"),AND(K135="ML",LOWER(B135)="liter")),0.001,1) -> 1
A136: =IFERROR(INDEX('Data SO'!$C$2:$C$1085,MATCH($J136,'Data SO'!$H$2:$H$1085,0)),INDEX('Data SCM'!$B$2:$B$698,MATCH($J136,'Data SCM'!$I$2:$I$698,0))) -> LILIN KRITING BIRU @1X100 PACK | B136: =IFERROR(INDEX('Data SO'!$D$2:$D$1085,MATCH($J136,'Data SO'!$H$2:$H$1085,0)),K136) -> Pcs | C136: =SUMIF('Data SO'!$H$2:$H$1085,$J136,'Data SO'!$F$2:$F$1085) -> 618 | D136: =SUMIF('Data SCM'!$I$2:$I$698,$J136,'Data SCM'!$E$2:$E$698)*L136 -> 618 | E136: =D136-C136 -> 0 | F136: =SUMIF('Data SO'!$H$2:$H$1085,$J136,'Data SO'!$G$2:$G$1085) -> 515000 | G136: =SUMIF('Data SCM'!$I$2:$I$698,$J136,'Data SCM'!$H$2:$H$698) -> 514999.98 | H136: =G136-F136 -> -0.0206 | I136: =IF(COUNTIF('Data SCM'!$I$2:$I$698,$J136)=0,"Hanya di SO",IF(COUNTIF('Data SO'!$H$2:$H$1085,$J136)=0,"Hanya di SCM",IF(AND(ABS(E136)<0.01,ABS(H136)<1),"Sama",IF(ABS(E136)<0.01,"Selisih nominal",IF(ABS(H136)<1,"Selisih qty","Selisih qty & nominal"))))) -> Sama | J136: lilinkritingbiru1x100pack | K136: =IFERROR(INDEX('Data SCM'!$D$2:$D$698,MATCH($J136,'Data SCM'!$I$2:$I$698,0)),"") -> PCS | L136: =IF(OR(AND(K136="GR",LOWER(B136)="kg"),AND(K136="ML",LOWER(B136)="liter")),0.001,1) -> 1
A137: =IFERROR(INDEX('Data SO'!$C$2:$C$1085,MATCH($J137,'Data SO'!$H$2:$H$1085,0)),INDEX('Data SCM'!$B$2:$B$698,MATCH($J137,'Data SCM'!$I$2:$I$698,0))) -> Lilin Kriting Rose Gold @1x100 pack | B137: =IFERROR(INDEX('Data SO'!$D$2:$D$1085,MATCH($J137,'Data SO'!$H$2:$H$1085,0)),K137) -> pcs | C137: =SUMIF('Data SO'!$H$2:$H$1085,$J137,'Data SO'!$F$2:$F$1085) -> 600 | D137: =SUMIF('Data SCM'!$I$2:$I$698,$J137,'Data SCM'!$E$2:$E$698)*L137 -> 600 | E137: =D137-C137 -> 0 | F137: =SUMIF('Data SO'!$H$2:$H$1085,$J137,'Data SO'!$G$2:$G$1085) -> 500000 | G137: =SUMIF('Data SCM'!$I$2:$I$698,$J137,'Data SCM'!$H$2:$H$698) -> 499999.98 | H137: =G137-F137 -> -0.02 | I137: =IF(COUNTIF('Data SCM'!$I$2:$I$698,$J137)=0,"Hanya di SO",IF(COUNTIF('Data SO'!$H$2:$H$1085,$J137)=0,"Hanya di SCM",IF(AND(ABS(E137)<0.01,ABS(H137)<1),"Sama",IF(ABS(E137)<0.01,"Selisih nominal",IF(ABS(H137)<1,"Selisih qty","Selisih qty & nominal"))))) -> Sama | J137: lilinkritingrosegold1x100pack | K137: =IFERROR(INDEX('Data SCM'!$D$2:$D$698,MATCH($J137,'Data SCM'!$I$2:$I$698,0)),"") -> PCS | L137: =IF(OR(AND(K137="GR",LOWER(B137)="kg"),AND(K137="ML",LOWER(B137)="liter")),0.001,1) -> 1
A138: =IFERROR(INDEX('Data SO'!$C$2:$C$1085,MATCH($J138,'Data SO'!$H$2:$H$1085,0)),INDEX('Data SCM'!$B$2:$B$698,MATCH($J138,'Data SCM'!$I$2:$I$698,0))) -> Palmia Bos @1X15Kg | B138: =IFERROR(INDEX('Data SO'!$D$2:$D$1085,MATCH($J138,'Data SO'!$H$2:$H$1085,0)),K138) -> kg | C138: =SUMIF('Data SO'!$H$2:$H$1085,$J138,'Data SO'!$F$2:$F$1085) -> 555 | D138: =SUMIF('Data SCM'!$I$2:$I$698,$J138,'Data SCM'!$E$2:$E$698)*L138 -> 555 | E138: =D138-C138 -> 0 | F138: =SUMIF('Data SO'!$H$2:$H$1085,$J138,'Data SO'!$G$2:$G$1085) -> 24682700 | G138: =SUMIF('Data SCM'!$I$2:$I$698,$J138,'Data SCM'!$H$2:$H$698) -> 24682700 | H138: =G138-F138 -> -0.0185 | I138: =IF(COUNTIF('Data SCM'!$I$2:$I$698,$J138)=0,"Hanya di SO",IF(COUNTIF('Data SO'!$H$2:$H$1085,$J138)=0,"Hanya di SCM",IF(AND(ABS(E138)<0.01,ABS(H138)<1),"Sama",IF(ABS(E138)<0.01,"Selisih nominal",IF(ABS(H138)<1,"Selisih qty","Selisih qty & nominal"))))) -> Sama | J138: palmiabos1x15kg | K138: =IFERROR(INDEX('Data SCM'!$D$2:$D$698,MATCH($J138,'Data SCM'!$I$2:$I$698,0)),"") -> KG | L138: =IF(OR(AND(K138="GR",LOWER(B138)="kg"),AND(K138="ML",LOWER(B138)="liter")),0.001,1) -> 1
A139: =IFERROR(INDEX('Data SO'!$C$2:$C$1085,MATCH($J139,'Data SO'!$H$2:$H$1085,0)),INDEX('Data SCM'!$B$2:$B$698,MATCH($J139,'Data SCM'!$I$2:$I$698,0))) -> PEWARNA CROSS SUPER RED @60ML | B139: =IFERROR(INDEX('Data SO'!$D$2:$D$1085,MATCH($J139,'Data SO'!$H$2:$H$1085,0)),K139) -> ml | C139: =SUMIF('Data SO'!$H$2:$H$1085,$J139,'Data SO'!$F$2:$F$1085) -> 540 | D139: =SUMIF('Data SCM'!$I$2:$I$698,$J139,'Data SCM'!$E$2:$E$698)*L139 -> 540 | E139: =D139-C139 -> 0 | F139: =SUMIF('Data SO'!$H$2:$H$1085,$J139,'Data SO'!$G$2:$G$1085) -> 495000 | G139: =SUMIF('Data SCM'!$I$2:$I$698,$J139,'Data SCM'!$H$2:$H$698) -> 495000.02 | H139: =G139-F139 -> 0.018 | I139: =IF(COUNTIF('Data SCM'!$I$2:$I$698,$J139)=0,"Hanya di SO",IF(COUNTIF('Data SO'!$H$2:$H$1085,$J139)=0,"Hanya di SCM",IF(AND(ABS(E139)<0.01,ABS(H139)<1),"Sama",IF(ABS(E139)<0.01,"Selisih nominal",IF(ABS(H139)<1,"Selisih qty","Selisih qty & nominal"))))) -> Sama | J139: pewarnacrosssuperred60ml | K139: =IFERROR(INDEX('Data SCM'!$D$2:$D$698,MATCH($J139,'Data SCM'!$I$2:$I$698,0)),"") -> ML | L139: =IF(OR(AND(K139="GR",LOWER(B139)="kg"),AND(K139="ML",LOWER(B139)="liter")),0.001,1) -> 1
A140: =IFERROR(INDEX('Data SO'!$C$2:$C$1085,MATCH($J140,'Data SO'!$H$2:$H$1085,0)),INDEX('Data SCM'!$B$2:$B$698,MATCH($J140,'Data SCM'!$I$2:$I$698,0))) -> Lilin Kriting purple @1x100 pack | B140: =IFERROR(INDEX('Data SO'!$D$2:$D$1085,MATCH($J140,'Data SO'!$H$2:$H$1085,0)),K140) -> pcs | C140: =SUMIF('Data SO'!$H$2:$H$1085,$J140,'Data SO'!$F$2:$F$1085) -> 420 | D140: =SUMIF('Data SCM'!$I$2:$I$698,$J140,'Data SCM'!$E$2:$E$698)*L140 -> 420 | E140: =D140-C140 -> 0 | F140: =SUMIF('Data SO'!$H$2:$H$1085,$J140,'Data SO'!$G$2:$G$1085) -> 350000 | G140: =SUMIF('Data SCM'!$I$2:$I$698,$J140,'Data SCM'!$H$2:$H$698) -> 349999.99 | H140: =G140-F140 -> -0.014 | I140: =IF(COUNTIF('Data SCM'!$I$2:$I$698,$J140)=0,"Hanya di SO",IF(COUNTIF('Data SO'!$H$2:$H$1085,$J140)=0,"Hanya di SCM",IF(AND(ABS(E140)<0.01,ABS(H140)<1),"Sama",IF(ABS(E140)<0.01,"Selisih nominal",IF(ABS(H140)<1,"Selisih qty","Selisih qty & nominal"))))) -> Sama | J140: lilinkritingpurple1x100pack | K140: =IFERROR(INDEX('Data SCM'!$D$2:$D$698,MATCH($J140,'Data SCM'!$I$2:$I$698,0)),"") -> PCS | L140: =IF(OR(AND(K140="GR",LOWER(B140)="kg"),AND(K140="ML",LOWER(B140)="liter")),0.001,1) -> 1
...

Sheet Data SO
A1: Sheet Sumber | B1: Kode Barang | C1: Nama Barang | D1: Uom | E1: Harga | F1: Qty Stok | G1: Jumlah (Rp) | H1: Key
A2: BAHAN BAKU | B2: 700107 | C2: 22% Reduced Fat Natural Cheddar Cheese Block @8X2.5 Kg | D2: kg | E2: 110000 | F2: 0 | G2: 0 | H2: 22reducedfatnaturalcheddarcheeseblock8x25kg
A3: BAHAN BAKU | B3: 400101 | C3: Abon | D3: kg | E3: 197500 | F3: 0 | G3: 0 | H3: abon
A4: BAHAN BAKU | B4: 400108 | C4: Abon Ayam | D4: kg | E4: 146520 | F4: 197 | G4: 28864440 | H4: abonayam
A5: BAHAN BAKU | B5: 200113 | C5: Acta Classic @1X10 Kg | D5: kg | E5: 63000 | F5: 0 | G5: 0 | H5: actaclassic1x10kg
A6: BAHAN BAKU | B6: 140302 | C6: DECORGEL NEUTRAL 3,15 KG | D6: kg | E6: 117660 | F6: 0 | G6: 0 | H6: decorgelneutral315kg
A7: BAHAN BAKU | B7: 111101 | C7: Alang-Alang | D7: Pcs | E7: 0 | F7: 0 | G7: 0 | H7: alangalang
A8: BAHAN BAKU | B8: 222101 | C8: Alas Bulat Emas Kecil | D8: pcs | E8: 240 | F8: 600 | G8: 144000 | H8: alasbulatemaskecil
A9: BAHAN BAKU | B9: 111102 | C9: Alas Segitiga Emas Kecil | D9: pcs | E9: 445 | F9: 700 | G9: 311500 | H9: alassegitigaemaskecil
A10: BAHAN BAKU | B10: 300208 | C10: Alba Shredded Mozarella 6X2 Kg | D10: kg | E10: 120000 | F10: 0 | G10: 0 | H10: albashreddedmozarella6x2kg
A11: BAHAN BAKU | B11: 400102 | C11: Almonesia | D11: kg | E11: 185185.19 | F11: 76.34 | G11: 14137037 | H11: almonesia
A12: BAHAN BAKU | B12: 700110 | C12: ALBA GRATED PARMESAN 6X2 KG | D12: kg | E12: 94427.083 | F12: 0 | G12: 0 | H12: albagratedparmesan6x2kg
A13: BAHAN BAKU | B13: 800101 | C13: Amanda Margarin @1X15Kg | D13: kg | E13: 18286.667 | F13: 150 | G13: 2743000 | H13: amandamargarin1x15kg
... A78: BAHAN BAKU | B78: 100208 | C78: Chefmate Stick Dark @8X1Kg | D78: Kg | E78: 94812.5 | F78: 304 | G78: 28823000 | H78: chefmatestickdark8x1kg
A79: BAHAN BAKU | B79: 100207 | C79: Chefmate White @ 12X1 Kg | D79: 0 | E79: 62781.25 | F79: 0 | G79: 0 | H79: chefmatewhite12x1kg
A80: BAHAN BAKU | B80: 100214 | C80: Chefmate White Compound 1Kg Pattisier | D80: Kg | E80: 61329.167 | F80: 0 | G80: 0 | H80: chefmatewhitecompound1kgpattisier
A81: BAHAN BAKU | B81: 300105 | C81: Chessy Natural Cream Cheese @2Kg | D81: kg | E81: 100000 | F81: 0 | G81: 0 | H81: chessynaturalcreamcheese2kg
A82: BAHAN BAKU | B82: 300106 | C82: Chessy Process Cream Cheese @1.9Kg | D82: Kg | E82: 87368.421 | F82: 93.1 | G82: 8134000 | H82: chessyprocesscreamcheese19kg
A83: BAHAN BAKU | B83: 400110 | C83: Chopped Peanut @10Kg | D83: kg | E83: 45000 | F83: 0 | G83: 0 | H83: choppedpeanut10kg
A84: BAHAN BAKU | B84: 100302 | C84: Collata Choco Chips | D84: Kg | E84: 70700 | F84: 0 | G84: 0 | H84: collatachocochips
A85: BAHAN BAKU | B85: 140707 | C85: CHEFMATE PASTE CHOCO CRUNCH 4X5 KG | D85: kg | E85: 70263.75 | F85: 920 | G85: 64642650 | H85: chefmatepastechococrunch4x5kg
A86: BAHAN BAKU | B86: 333101 | C86: Cover Dessert Blueberry | D86: Pcs | E86: 1450 | F86: 4800 | G86: 6960000 | H86: coverdessertblueberry
A87: BAHAN BAKU | B87: 333102 | C87: Cover Dessert Chocolate | D87: Pcs | E87: 1000 | F87: 436 | G87: 436000 | H87: coverdessertchocolate
A88: BAHAN BAKU | B88: 333103 | C88: Cover Dessert Mango | D88: Pcs | E88: 1450 | F88: 1698 | G88: 2462100 | H88: coverdessertmango
A89: BAHAN BAKU | B89: 140202 | C89: Crystal Jelly @5Kg | D89: kg | E89: 71192.6 | F89: 5 | G89: 355963 | H89: crystaljelly5kg
A90: BAHAN BAKU | B90: 140300 | C90: Decorgel Glamour @1X3,15Kg | D90: kg | E90: 166500 | F90: 0 | G90: 0 | H90: decorgelglamour1x315kg
A91: BAHAN BAKU | B91: 333104 | C91: COVER HAMPERS | D91: pcs | E91: 0 | F91: 0 | G91: 0 | H91: coverhampers
... A524: BAHAN BAKU | B524: 444301 | C524: Gas 12 Kg Bogor | D524: kg | E524: 19000 | F524: 0 | G524: 0 | H524: gas12kgbogor
A525: BAHAN BAKU | B525: 444701 | C525: Icipon | D525: 1 | E525: 26000 | F525: 0 | G525: 0 | H525: icipon
A526: BAHAN BAKU | B526: 400201 | C526: Pisang Ambon Matang | D526: kg | E526: 10000 | F526: 0 | G526: 0 | H526: pisangambonmatang
A527: BAHAN BAKU | B527: 400202 | C527: Pisang Ambon Mentah | D527: kg | E527: 5000 | F527: 0 | G527: 0 | H527: pisangambonmentah
A528: BAHAN BAKU | B528: 400203 | C528: Pisang Raja Ajo | D528: kg | E528: 11000 | F528: 0 | G528: 0 | H528: pisangrajaajo
A529: BAHAN BAKU | B529: 400204 | C529: Pisang Raja Matang | D529: kg | E529: 10500 | F529: 130.6 | G529: 1371300 | H529: pisangrajamatang
A530: BAHAN BAKU | B530: 400205 | C530: Pisang Raja Mentah | D530: kg | E530: 10500 | F530: 0 | G530: 0 | H530: pisangrajamentah
A531: BAHAN BAKU | B531: 400505 | C531: Telur Ayam Non Sortir | D531: kg | E531: 27000 | F531: 0 | G531: 0 | H531: telurayamnonsortir
A532: BAHAN BAKU | B532: 400501 | C532: Telur Merah Grade A (Asb) | D532: kg | E532: 30000 | F532: 0 | G532: 0 | H532: telurmerahgradeaasb
A533: BAHAN BAKU | B533: 400502 | C533: TELUR | D533: kg | E533: 26500 | F533: 1065 | G533: 28222500 | H533: telur
A534: BAHAN BAKU | B534: 400503 | C534: TELUR MERAH GRADE B BOGOR | D534: kg | E534: 27000 | F534: 0 | G534: 0 | H534: telurmerahgradebbogor
A535: BAHAN BAKU | B535: 400504 | C535: Telur Putih | D535: kg | E535: 26700 | F535: 0 | G535: 0 | H535: telurputih
A536: BAHAN BAKU | B536: 400506 | C536: Telur Putih Retak | D536: kg | E536: 25200 | F536: 0 | G536: 0 | H536: telurputihretak
...

Sheet Data SCM
A1: SKU | B1: Nama Produk | C1: Kategori | D1: Satuan | E1: Stok Tersedia | F1: Stok Minimal | G1: Status | H1: Nilai Stok (Rp) | I1: Key
A2: RM-FS-26-008 | B2: Abon Ayam | C2: Fruits & Seeds | D2: KG | E2: 197 | F2: 9 | G2: AMAN | H2: 28864440 | I2: abonayam
A3: RM-FS-26-034 | B3: Abon Ayam Pedas | C3: Fruits & Seeds | D3: KG | E3: 71 | F3: 5 | G3: AMAN | H3: 10796970 | I3: abonayampedas
A4: RM-FS-26-032 | B4: Abon Sapi Piala @4X1Kg | C4: Fruits & Seeds | D4: KG | E4: 44 | F4: 50 | G4: WARNING | H4: 4713060 | I4: abonsapipiala4x1kg
A5: RM-FS-26-033 | B5: Abon Sapi Piala Pedas @4X1Kg | C5: Fruits & Seeds | D5: KG | E5: 0 | F5: 1 | G5: HABIS | H5: 0 | I5: abonsapipialapedas4x1kg
A6: RM-TF-26-061 | B6: Agar-Agar Swallow | C6: Toping/Filling | D6: PCS | E6: 17 | F6: 4 | G6: AMAN | H6: 5950 | I6: agaragarswallow
A7: RM-PX-26-128 | B7: Air Mineral 200 Ml | C7: Premix | D7: ML | E7: 0 | F7: 0 | G7: HABIS | H7: 0 | I7: airmineral200ml
A8: RM-PX-26-145 | B8: Air Mineral 220 Ml | C8: Premix | D8: PCS | E8: 3 | F8: 68000 | G8: WARNING | H8: 2750.0001 | I8: airmineral220ml
A9: RM-PX-26-149 | B9: Air Mineral 330 Ml | C9: Premix | D9: ML | E9: 0 | F9: 0 | G9: HABIS | H9: 0 | I9: airmineral330ml
A10: RM-AL-26-001 | B10: Alas Bulat Emas Kecil | C10: Alas Kue | D10: PCS | E10: 600 | F10: 55 | G10: AMAN | H10: 144000 | I10: alasbulatemaskecil
A11: RM-AL-26-020 | B11: Alas Kotak 10X10 | C11: Alas Kue | D11: PCS | E11: 400 | F11: 51 | G11: AMAN | H11: 240000 | I11: alaskotak10x10
A12: RM-AL-26-015 | B12: Alas Kotak Emas Kecil | C12: Alas Kue | D12: PCS | E12: 1250 | F12: 216 | G12: AMAN | H12: 710000 | I12: alaskotakemaskecil
A13: RM-AK-26-002 | B13: Alas Segitiga Emas Kecil | C13: Aksesoris | D13: PCS | E13: 700 | F13: 400 | G13: AMAN | H13: 311500 | I13: alassegitigaemaskecil
... A698: RM-SS-26-012 | B698: Zee Strawberry | C698: Susu | D698: GR | E698: 14280 | F698: 0 | G698: AMAN | H698: 2267999.6 | I698: zeestrawberry
